[2020-01-02 18:06:11,818] {/home/alta15/virenv/flask_virenv/lib/python3.6/site-packages/flask/app.py:1891} ERROR - Exception on /product [GET]
Traceback (most recent call last):
  File "/home/alta15/virenv/flask_virenv/lib/python3.6/site-packages/flask/app.py", line 1949, in full_dispatch_request
    rv = self.dispatch_request()
  File "/home/alta15/virenv/flask_virenv/lib/python3.6/site-packages/flask/app.py", line 1935, in dispatch_request
    return self.view_functions[rule.endpoint](**req.view_args)
  File "/home/alta15/virenv/flask_virenv/lib/python3.6/site-packages/flask_restful/__init__.py", line 458, in wrapper
    resp = resource(*args, **kwargs)
  File "/home/alta15/virenv/flask_virenv/lib/python3.6/site-packages/flask/views.py", line 89, in view
    return self.dispatch_request(*args, **kwargs)
  File "/home/alta15/virenv/flask_virenv/lib/python3.6/site-packages/flask_restful/__init__.py", line 573, in dispatch_request
    resp = meth(*args, **kwargs)
  File "/home/alta15/flask/gudangworkout/blueprints/product/resources.py", line 93, in get
    for row in products.limit(int(args['rp'])).offset(indeks_mulai).all():
UnboundLocalError: local variable 'products' referenced before assignment
[2020-01-02 18:06:48,290] {/home/alta15/virenv/flask_virenv/lib/python3.6/site-packages/flask/app.py:1891} ERROR - Exception on /product [GET]
Traceback (most recent call last):
  File "/home/alta15/virenv/flask_virenv/lib/python3.6/site-packages/flask/app.py", line 1949, in full_dispatch_request
    rv = self.dispatch_request()
  File "/home/alta15/virenv/flask_virenv/lib/python3.6/site-packages/flask/app.py", line 1935, in dispatch_request
    return self.view_functions[rule.endpoint](**req.view_args)
  File "/home/alta15/virenv/flask_virenv/lib/python3.6/site-packages/flask_restful/__init__.py", line 458, in wrapper
    resp = resource(*args, **kwargs)
  File "/home/alta15/virenv/flask_virenv/lib/python3.6/site-packages/flask/views.py", line 89, in view
    return self.dispatch_request(*args, **kwargs)
  File "/home/alta15/virenv/flask_virenv/lib/python3.6/site-packages/flask_restful/__init__.py", line 573, in dispatch_request
    resp = meth(*args, **kwargs)
  File "/home/alta15/flask/gudangworkout/blueprints/product/resources.py", line 93, in get
    for row in products.limit(int(args['rp'])).offset(indeks_mulai).all():
UnboundLocalError: local variable 'products' referenced before assignment
[2020-01-02 18:21:54,418] {/home/alta15/virenv/flask_virenv/lib/python3.6/site-packages/flask/app.py:1891} ERROR - Exception on /product [GET]
Traceback (most recent call last):
  File "/home/alta15/virenv/flask_virenv/lib/python3.6/site-packages/flask/app.py", line 1949, in full_dispatch_request
    rv = self.dispatch_request()
  File "/home/alta15/virenv/flask_virenv/lib/python3.6/site-packages/flask/app.py", line 1935, in dispatch_request
    return self.view_functions[rule.endpoint](**req.view_args)
  File "/home/alta15/virenv/flask_virenv/lib/python3.6/site-packages/flask_restful/__init__.py", line 462, in wrapper
    return self.make_response(data, code, headers=headers)
  File "/home/alta15/virenv/flask_virenv/lib/python3.6/site-packages/flask_restful/__init__.py", line 491, in make_response
    resp = self.representations[mediatype](data, *args, **kwargs)
  File "/home/alta15/virenv/flask_virenv/lib/python3.6/site-packages/flask_restful/representations/json.py", line 21, in output_json
    dumped = dumps(data, **settings) + "\n"
  File "/usr/lib/python3.6/json/__init__.py", line 231, in dumps
    return _default_encoder.encode(obj)
  File "/usr/lib/python3.6/json/encoder.py", line 199, in encode
    chunks = self.iterencode(o, _one_shot=True)
  File "/usr/lib/python3.6/json/encoder.py", line 257, in iterencode
    return _iterencode(o, 0)
  File "/usr/lib/python3.6/json/encoder.py", line 180, in default
    o.__class__.__name__)
TypeError: Object of type 'Decimal' is not JSON serializable
[2020-01-02 18:23:40,585] {/home/alta15/virenv/flask_virenv/lib/python3.6/site-packages/flask/app.py:1891} ERROR - Exception on /product [GET]
Traceback (most recent call last):
  File "/home/alta15/virenv/flask_virenv/lib/python3.6/site-packages/flask/app.py", line 1949, in full_dispatch_request
    rv = self.dispatch_request()
  File "/home/alta15/virenv/flask_virenv/lib/python3.6/site-packages/flask/app.py", line 1935, in dispatch_request
    return self.view_functions[rule.endpoint](**req.view_args)
  File "/home/alta15/virenv/flask_virenv/lib/python3.6/site-packages/flask_restful/__init__.py", line 458, in wrapper
    resp = resource(*args, **kwargs)
  File "/home/alta15/virenv/flask_virenv/lib/python3.6/site-packages/flask/views.py", line 89, in view
    return self.dispatch_request(*args, **kwargs)
  File "/home/alta15/virenv/flask_virenv/lib/python3.6/site-packages/flask_restful/__init__.py", line 573, in dispatch_request
    resp = meth(*args, **kwargs)
  File "/home/alta15/flask/gudangworkout/blueprints/product/resources.py", line 72, in get
    results.append({'total_sold_qty': product_sale['total_sold_qty']})
TypeError: tuple indices must be integers or slices, not str
[2020-01-02 18:24:24,244] {/home/alta15/virenv/flask_virenv/lib/python3.6/site-packages/flask/app.py:1891} ERROR - Exception on /product [GET]
Traceback (most recent call last):
  File "/home/alta15/virenv/flask_virenv/lib/python3.6/site-packages/flask/app.py", line 1949, in full_dispatch_request
    rv = self.dispatch_request()
  File "/home/alta15/virenv/flask_virenv/lib/python3.6/site-packages/flask/app.py", line 1935, in dispatch_request
    return self.view_functions[rule.endpoint](**req.view_args)
  File "/home/alta15/virenv/flask_virenv/lib/python3.6/site-packages/flask_restful/__init__.py", line 458, in wrapper
    resp = resource(*args, **kwargs)
  File "/home/alta15/virenv/flask_virenv/lib/python3.6/site-packages/flask/views.py", line 89, in view
    return self.dispatch_request(*args, **kwargs)
  File "/home/alta15/virenv/flask_virenv/lib/python3.6/site-packages/flask_restful/__init__.py", line 573, in dispatch_request
    resp = meth(*args, **kwargs)
  File "/home/alta15/flask/gudangworkout/blueprints/product/resources.py", line 72, in get
    results.append({'total_sold_qty': product_sale('total_sold_qty')})
TypeError: 'result' object is not callable
[2020-01-02 18:41:05,399] {/home/alta15/virenv/flask_virenv/lib/python3.6/site-packages/flask/app.py:1891} ERROR - Exception on /product [GET]
Traceback (most recent call last):
  File "/home/alta15/virenv/flask_virenv/lib/python3.6/site-packages/flask/app.py", line 1949, in full_dispatch_request
    rv = self.dispatch_request()
  File "/home/alta15/virenv/flask_virenv/lib/python3.6/site-packages/flask/app.py", line 1935, in dispatch_request
    return self.view_functions[rule.endpoint](**req.view_args)
  File "/home/alta15/virenv/flask_virenv/lib/python3.6/site-packages/flask_restful/__init__.py", line 458, in wrapper
    resp = resource(*args, **kwargs)
  File "/home/alta15/virenv/flask_virenv/lib/python3.6/site-packages/flask/views.py", line 89, in view
    return self.dispatch_request(*args, **kwargs)
  File "/home/alta15/virenv/flask_virenv/lib/python3.6/site-packages/flask_restful/__init__.py", line 573, in dispatch_request
    resp = meth(*args, **kwargs)
  File "/home/alta15/flask/gudangworkout/blueprints/product/resources.py", line 72, in get
    results.append({'total_sold_qty': product_sale('total_sold_qty')})
TypeError: 'result' object is not callable
[2020-01-02 18:46:01,140] {/home/alta15/virenv/flask_virenv/lib/python3.6/site-packages/flask/app.py:1891} ERROR - Exception on /product [GET]
Traceback (most recent call last):
  File "/home/alta15/virenv/flask_virenv/lib/python3.6/site-packages/flask/app.py", line 1949, in full_dispatch_request
    rv = self.dispatch_request()
  File "/home/alta15/virenv/flask_virenv/lib/python3.6/site-packages/flask/app.py", line 1935, in dispatch_request
    return self.view_functions[rule.endpoint](**req.view_args)
  File "/home/alta15/virenv/flask_virenv/lib/python3.6/site-packages/flask_restful/__init__.py", line 458, in wrapper
    resp = resource(*args, **kwargs)
  File "/home/alta15/virenv/flask_virenv/lib/python3.6/site-packages/flask/views.py", line 89, in view
    return self.dispatch_request(*args, **kwargs)
  File "/home/alta15/virenv/flask_virenv/lib/python3.6/site-packages/flask_restful/__init__.py", line 573, in dispatch_request
    resp = meth(*args, **kwargs)
  File "/home/alta15/flask/gudangworkout/blueprints/product/resources.py", line 39, in get
    print(product_sales[2].total_sold_qty)
  File "/home/alta15/virenv/flask_virenv/lib/python3.6/site-packages/sqlalchemy/orm/query.py", line 3048, in __getitem__
    return list(self[item : item + 1])[0]
IndexError: list index out of range
[2020-01-02 18:48:16,806] {/home/alta15/virenv/flask_virenv/lib/python3.6/site-packages/flask/app.py:1891} ERROR - Exception on /product [GET]
Traceback (most recent call last):
  File "/home/alta15/virenv/flask_virenv/lib/python3.6/site-packages/flask/app.py", line 1949, in full_dispatch_request
    rv = self.dispatch_request()
  File "/home/alta15/virenv/flask_virenv/lib/python3.6/site-packages/flask/app.py", line 1935, in dispatch_request
    return self.view_functions[rule.endpoint](**req.view_args)
  File "/home/alta15/virenv/flask_virenv/lib/python3.6/site-packages/flask_restful/__init__.py", line 458, in wrapper
    resp = resource(*args, **kwargs)
  File "/home/alta15/virenv/flask_virenv/lib/python3.6/site-packages/flask/views.py", line 89, in view
    return self.dispatch_request(*args, **kwargs)
  File "/home/alta15/virenv/flask_virenv/lib/python3.6/site-packages/flask_restful/__init__.py", line 573, in dispatch_request
    resp = meth(*args, **kwargs)
  File "/home/alta15/flask/gudangworkout/blueprints/product/resources.py", line 75, in get
    print(len(product_sales))
TypeError: object of type 'BaseQuery' has no len()
