[2020-01-02 20:05:07,399] {/home/alta15/virenv/flask_virenv/lib/python3.6/site-packages/flask/app.py:1891} ERROR - Exception on /product [GET]
Traceback (most recent call last):
  File "/home/alta15/virenv/flask_virenv/lib/python3.6/site-packages/flask/app.py", line 1949, in full_dispatch_request
    rv = self.dispatch_request()
  File "/home/alta15/virenv/flask_virenv/lib/python3.6/site-packages/flask/app.py", line 1935, in dispatch_request
    return self.view_functions[rule.endpoint](**req.view_args)
  File "/home/alta15/virenv/flask_virenv/lib/python3.6/site-packages/flask_restful/__init__.py", line 458, in wrapper
    resp = resource(*args, **kwargs)
  File "/home/alta15/virenv/flask_virenv/lib/python3.6/site-packages/flask/views.py", line 89, in view
    return self.dispatch_request(*args, **kwargs)
  File "/home/alta15/virenv/flask_virenv/lib/python3.6/site-packages/flask_restful/__init__.py", line 573, in dispatch_request
    resp = meth(*args, **kwargs)
  File "/home/alta15/flask/gudangworkout/blueprints/product/resources.py", line 40, in get
    print(product_sales[1]['name'])
TypeError: tuple indices must be integers or slices, not str
[2020-01-02 20:05:32,408] {/home/alta15/virenv/flask_virenv/lib/python3.6/site-packages/flask/app.py:1891} ERROR - Exception on /product [GET]
Traceback (most recent call last):
  File "/home/alta15/virenv/flask_virenv/lib/python3.6/site-packages/flask/app.py", line 1949, in full_dispatch_request
    rv = self.dispatch_request()
  File "/home/alta15/virenv/flask_virenv/lib/python3.6/site-packages/flask/app.py", line 1935, in dispatch_request
    return self.view_functions[rule.endpoint](**req.view_args)
  File "/home/alta15/virenv/flask_virenv/lib/python3.6/site-packages/flask_restful/__init__.py", line 458, in wrapper
    resp = resource(*args, **kwargs)
  File "/home/alta15/virenv/flask_virenv/lib/python3.6/site-packages/flask/views.py", line 89, in view
    return self.dispatch_request(*args, **kwargs)
  File "/home/alta15/virenv/flask_virenv/lib/python3.6/site-packages/flask_restful/__init__.py", line 573, in dispatch_request
    resp = meth(*args, **kwargs)
  File "/home/alta15/flask/gudangworkout/blueprints/product/resources.py", line 40, in get
    print(product_sales[1]('name'))
TypeError: 'result' object is not callable
[2020-01-02 20:05:54,154] {/home/alta15/virenv/flask_virenv/lib/python3.6/site-packages/flask/app.py:1891} ERROR - Exception on /product [GET]
Traceback (most recent call last):
  File "/home/alta15/virenv/flask_virenv/lib/python3.6/site-packages/flask/app.py", line 1949, in full_dispatch_request
    rv = self.dispatch_request()
  File "/home/alta15/virenv/flask_virenv/lib/python3.6/site-packages/flask/app.py", line 1935, in dispatch_request
    return self.view_functions[rule.endpoint](**req.view_args)
  File "/home/alta15/virenv/flask_virenv/lib/python3.6/site-packages/flask_restful/__init__.py", line 458, in wrapper
    resp = resource(*args, **kwargs)
  File "/home/alta15/virenv/flask_virenv/lib/python3.6/site-packages/flask/views.py", line 89, in view
    return self.dispatch_request(*args, **kwargs)
  File "/home/alta15/virenv/flask_virenv/lib/python3.6/site-packages/flask_restful/__init__.py", line 573, in dispatch_request
    resp = meth(*args, **kwargs)
  File "/home/alta15/flask/gudangworkout/blueprints/product/resources.py", line 40, in get
    print(product_sales[1](name))
NameError: name 'name' is not defined
[2020-01-02 20:27:57,563] {/home/alta15/virenv/flask_virenv/lib/python3.6/site-packages/flask/app.py:1891} ERROR - Exception on /product [GET]
Traceback (most recent call last):
  File "/home/alta15/virenv/flask_virenv/lib/python3.6/site-packages/flask/app.py", line 1949, in full_dispatch_request
    rv = self.dispatch_request()
  File "/home/alta15/virenv/flask_virenv/lib/python3.6/site-packages/flask/app.py", line 1935, in dispatch_request
    return self.view_functions[rule.endpoint](**req.view_args)
  File "/home/alta15/virenv/flask_virenv/lib/python3.6/site-packages/flask_restful/__init__.py", line 458, in wrapper
    resp = resource(*args, **kwargs)
  File "/home/alta15/virenv/flask_virenv/lib/python3.6/site-packages/flask/views.py", line 89, in view
    return self.dispatch_request(*args, **kwargs)
  File "/home/alta15/virenv/flask_virenv/lib/python3.6/site-packages/flask_restful/__init__.py", line 573, in dispatch_request
    resp = meth(*args, **kwargs)
  File "/home/alta15/flask/gudangworkout/blueprints/product/resources.py", line 80, in get
    'id' : product_sale.id,
AttributeError: 'result' object has no attribute 'id'
[2020-01-02 20:29:24,583] {/home/alta15/virenv/flask_virenv/lib/python3.6/site-packages/flask/app.py:1891} ERROR - Exception on /product [GET]
Traceback (most recent call last):
  File "/home/alta15/virenv/flask_virenv/lib/python3.6/site-packages/flask/app.py", line 1949, in full_dispatch_request
    rv = self.dispatch_request()
  File "/home/alta15/virenv/flask_virenv/lib/python3.6/site-packages/flask/app.py", line 1935, in dispatch_request
    return self.view_functions[rule.endpoint](**req.view_args)
  File "/home/alta15/virenv/flask_virenv/lib/python3.6/site-packages/flask_restful/__init__.py", line 458, in wrapper
    resp = resource(*args, **kwargs)
  File "/home/alta15/virenv/flask_virenv/lib/python3.6/site-packages/flask/views.py", line 89, in view
    return self.dispatch_request(*args, **kwargs)
  File "/home/alta15/virenv/flask_virenv/lib/python3.6/site-packages/flask_restful/__init__.py", line 573, in dispatch_request
    resp = meth(*args, **kwargs)
  File "/home/alta15/flask/gudangworkout/blueprints/product/resources.py", line 91, in get
    'weight_gram' : product_sale.weight_gram,
AttributeError: 'result' object has no attribute 'weight_gram'
[2020-01-02 20:53:00,573] {/home/alta15/flask/gudangworkout/blueprints/__init__.py:96} INFO - REQUEST_LOG	{"status_code": 200, "method": "GET", "code": "200 OK", "uri": "/product/2?", "request": {}, "response": [{"id": 2, "name": "Evolene Mass Gainer 5,6lbs", "merchant_id": 2, "category_id": 2, "default_price": 650000, "brand_name": "Evolene", "country_of_origin": "Indonesia", "url_img1": "", "url_img2": "", "url_img3": "", "condition": "baru", "weight_gram": 3000, "short_description": "Susu bubuk whey protein penambah massa otot", "detail_product": "Tersedia berbagai pilihan rasa: Coklat, Original, Vanilla, Strawberry, Mocca, Banana", "is_available": true, "created_at": "Thu, 02 Jan 2020 10:16:30 -0000", "updated_at": null, "deleted": false}]}
[2020-01-02 22:14:19,866] {/home/alta15/flask/gudangworkout/blueprints/__init__.py:106} ERROR - REQUEST_LOG	{"status_code": 404, "method": "GET", "code": "404 NOT FOUND", "uri": "/orders?", "request": {}, "response": {"message": "The requested URL was not found on the server. If you entered the URL manually please check your spelling and try again."}}
[2020-01-02 22:14:47,919] {/home/alta15/flask/gudangworkout/blueprints/__init__.py:96} INFO - REQUEST_LOG	{"status_code": 200, "method": "GET", "code": "200 OK", "uri": "/merchant/orders?", "request": {}, "response": [{"id": 2, "sale_id": 1, "product_id": 11, "qty": 5, "price_on_sale": 150000, "discount_amount": 0, "total_shipping_fee": 26000, "total": 776000, "is_shipped": false, "created_at": "Thu, 02 Jan 2020 12:30:10 -0000", "updated_at": "Thu, 02 Jan 2020 14:23:27 -0000", "deleted": false}]}
[2020-01-02 22:16:14,194] {/home/alta15/flask/gudangworkout/blueprints/__init__.py:96} INFO - REQUEST_LOG	{"status_code": 200, "method": "GET", "code": "200 OK", "uri": "/product/2?", "request": {}, "response": [{"id": 2, "name": "Evolene Mass Gainer 5,6lbs", "merchant_id": 2, "category_id": 2, "default_price": 650000, "brand_name": "Evolene", "country_of_origin": "Indonesia", "url_img1": "", "url_img2": "", "url_img3": "", "condition": "baru", "weight_gram": 3000, "short_description": "Susu bubuk whey protein penambah massa otot", "detail_product": "Tersedia berbagai pilihan rasa: Coklat, Original, Vanilla, Strawberry, Mocca, Banana", "is_available": true, "created_at": "Thu, 02 Jan 2020 10:16:30 -0000", "updated_at": null, "deleted": false}]}
[2020-01-03 10:25:56,074] {/home/alta15/virenv/flask_virenv/lib/python3.6/site-packages/flask/app.py:1891} ERROR - Exception on /merchant/orders [GET]
Traceback (most recent call last):
  File "/home/alta15/virenv/flask_virenv/lib/python3.6/site-packages/flask/app.py", line 1949, in full_dispatch_request
    rv = self.dispatch_request()
  File "/home/alta15/virenv/flask_virenv/lib/python3.6/site-packages/flask/app.py", line 1935, in dispatch_request
    return self.view_functions[rule.endpoint](**req.view_args)
  File "/home/alta15/virenv/flask_virenv/lib/python3.6/site-packages/flask_restful/__init__.py", line 458, in wrapper
    resp = resource(*args, **kwargs)
  File "/home/alta15/virenv/flask_virenv/lib/python3.6/site-packages/flask/views.py", line 89, in view
    return self.dispatch_request(*args, **kwargs)
  File "/home/alta15/virenv/flask_virenv/lib/python3.6/site-packages/flask_restful/__init__.py", line 573, in dispatch_request
    resp = meth(*args, **kwargs)
  File "/home/alta15/virenv/flask_virenv/lib/python3.6/site-packages/flask_jwt_extended/view_decorators.py", line 107, in wrapper
    verify_jwt_in_request()
  File "/home/alta15/virenv/flask_virenv/lib/python3.6/site-packages/flask_jwt_extended/view_decorators.py", line 32, in verify_jwt_in_request
    jwt_data, jwt_header = _decode_jwt_from_request(request_type='access')
  File "/home/alta15/virenv/flask_virenv/lib/python3.6/site-packages/flask_jwt_extended/view_decorators.py", line 314, in _decode_jwt_from_request
    raise NoAuthorizationError(errors[0])
flask_jwt_extended.exceptions.NoAuthorizationError: Missing Authorization Header
